Workbook

Sheet 工事概要
A1: 起案日 | B1: =TODAY() -> 46065 | G1: 起案者 | H1: =見積書!H8 -> 伊藤 隆一
A3: 工事件名 | B3: =見積書!H5 -> 住吉屋様邸 改修工事 | E3: 住所 | F3: =見積書!H4 -> 神奈川県横浜市旭区希望ヶ丘230-9
A4: 受注先 | B4: =B8 -> 住林林業ホームテック㈱ | D4: 担当者 | G4: 電話番号 | K4: ← 色付きの部分は見積書・請求書の該当する部分に入力してください。 ここで入力しても、見積書や請求書には反映されません。
A5: 予定工期 | B5: =E10 | E5: ～
A6: 積算者 | D6: 実測 | E6: 図面 | F6: 内訳 | G6: 設計
A7: 見積状況
A8: 提出先 | B8: =見積書!A4 -> 住林林業ホームテック㈱ | D8: 担当者 | E8: =見積書!B5 -> 吉田 | G8: 受注 | H8: 決定 | I8: 取止
A9: 見積額 | B9: =見積書!B7 -> 3806000 | D9: 予算額 | G9: 取極額 | H9: =請求書!B7 -> 0
A10: 見積日 | B10: =見積書!H1 -> 44969 | D10: 施工日 | E10: =見積書!H7 | G10: 請求日 | H10: =請求書!H1 -> 45200
A11: 見積経緯
A12: 引合日
A15: 付記事項
A20: 所見
A24: 決裁
A25: 社 長 | B25: 鴻 上 真 | C25: 田 子 | D25: 鈴 木 逸 | E25: 神 塚 | F25: 伊 藤 | G25: 船 隈 | H25: 和 田
I27: 起案者

Sheet 見積書
H1: 44969
A2: 御 見 積 書
A4: 住林林業ホームテック㈱ | C4: 御中 | G4: 住 所 | H4: 神奈川県横浜市旭区希望ヶ丘230-9
B5: 吉田 | G5: 工 事 件 名 | H5: 住吉屋様邸 改修工事
B6: 御見積金額
B7: =G21 -> 3806000 | G7: 施 工 日
G8: 担 当 者 | H8: 伊藤 隆一
A9: 建設業許可 東京都知事（特-7）第20865号
A10: 名 称 | C10: 仕 様 | D10: 数 量 | E10: 単位 | F10: 単 価 | G10: 金 額 | H10: 摘 要
B11: 外壁塗装工事 | D11: 1 | E11: 式 | G11: =内訳!G11+内訳!G35+内訳!G40+内訳!G42 -> 3467015
B18: 値引き | G18: -7015
B19: 工 事 計 | G19: =SUBTOTAL(9,G$11:G18) -> 3460000
B20: 消費税 | D20: 10 | E20: ％ | G20: =G19*D20/100 -> 346000
B21: 合 計 | G21: =SUBTOTAL(9,G$11:G20) -> 3806000

Sheet 内訳
A1: 名 称 | C1: 仕 様 | D1: 数 量 | E1: 単位 | F1: 単 価 | G1: 金 額 | H1: 摘 要
A2: =ROW()-1 -> 1 | B2: 仮設工事 | G2: =D2*F2 -> 0
B3: 外部足場 | C3: くさび緊結式足場本足場 手摺２段 | D3: 430 | E3: ㎡ | F3: 1050 | G3: =D3*F3 -> 451500
B4: 屋根足場 | C4: ６寸 | D4: 189.9 | E4: ㎡ | F4: 850 | G4: =D4*F4 -> 161415
B5: 昇降設備 | D5: 1 | E5: 式 | F5: 15000 | G5: =D5*F5 -> 15000
B6: 運搬費 | C6: 場内小運搬込み | D6: 1 | E6: 式 | F6: 35000 | G6: =D6*F6 -> 35000
B7: 道路使用許可申請費 | D7: 1 | E7: 式 | F7: 15000 | G7: =D7*F7 -> 15000
B8: ガードマン | C8: 架け２名・払い2名 | D8: 4 | E8: 人 | F8: 24000 | G8: =D8*F8 -> 96000
B9: カーポート屋根脱着 バルコニー屋根脱着 | E9: 箇所 | F9: 50000 | G9: =D9*F9 -> 0
B10: 防護管設置費用 | D10: 1 | E10: 式 | F10: 80000 | G10: =D10*F10 -> 80000
B11: 小計 | G11: =SUM(G3:G10) -> 853915
G12: =D12*F12 -> 0
G13: =D13*F13 -> 0
G14: =D14*F14 -> 0
G15: =D15*F15 -> 0
G16: =D16*F16 -> 0
G17: =D17*F17 -> 0
G18: =D18*F18 -> 0
A19: 2 | B19: 塗装工事 | G19: =D19*F19 -> 0
B20: 屋根高圧洗浄 | D20: 189.9 | E20: ㎡ | F20: 200 | G20: =D20*F20 -> 37980
B21: 屋根板金塗装 | C21: ケレン+錆止め クリーンマイルドシリコン | D21: 1 | E21: 式 | F21: 38000 | G21: =D21*F21 -> 38000
B22: 屋根塗装 | C22: マイルドシーラーエポ クールタイトSi | D22: 189.9 | E22: ㎡ | F22: 2200 | G22: =D22*F22 -> 417780
B23: 縁切り | D23: 189.9 | E23: ㎡ | F23: 250 | G23: =D23*F23 -> 47475
B24: 外壁高圧洗浄 | D24: 237.8 | E24: ㎡ | F24: 150 | G24: =D24*F24 -> 35670
B25: 外壁塗装 | C25: ミラクシーラーエコ+ベース色 タイル色+パターン色 | D25: 237.8 | E25: ㎡ | F25: 4200 | G25: =D25*F25 -> 998760 | H25: トリプルトーン（ラジカル塗料）
B26: 土台・中間水切り塗装 | C26: ケレン+錆止め クリーンマイルドシリコン | D26: 82.2 | E26: ｍ | F26: 650 | G26: =D26*F26 -> 53430
B27: 出窓天端塗装 | C27: ケレン+錆止め クリーンマイルドシリコン | D27: 6.1 | E27: ｍ | F27: 1700 | G27: =D27*F27 -> 10370
B28: 化粧梁・付梁塗装 | C28: クリーンマイルドシリコン | D28: 1.8 | E28: ｍ | F28: 750 | G28: =D28*F28 -> 1350
B29: 破風・鼻隠し塗装 | C29: クリーンマイルドシリコン | D29: 74.6 | E29: ｍ | F29: 750 | G29: =D29*F29 -> 55950
B30: 軒天塗装（破風ｍ合わせ） | C30: クリーンマイルドシリコン | D30: 74.6 | E30: ｍ | F30: 950 | G30: =D30*F30 -> 70870
B31: 軒天塗装（玄関・バルコニー） | C31: クリーンマイルドシリコン | D31: 7.5 | E31: ㎡ | F31: 950 | G31: =D31*F31 -> 7125
B32: 雨樋塗装 | C32: クリーンマイルドシリコン | D32: 92.4 | E32: ｍ | F32: 650 | G32: =D32*F32 -> 60060
B33: シャッターボックス塗装 | C33: ケレン+錆止め クリーンマイルドシリコン | D33: 20.9 | E33: ｍ | F33: 1700 | G33: =D33*F33 -> 35530
B34: 基礎塗装 | C34: ベースプロテクト | D34: 1 | E34: 式 | F34: 60000 | G34: =D34*F34 -> 60000
B35: 小計 | G35: =SUM(G20:G34) -> 1930350
A36: 3 | B36: シーリング工事
B37: サイデイング目地シーリング | C37: オートンイクシード 打ち替え | D37: 385 | E37: ｍ | F37: 1150 | G37: =D37*F37 -> 442750
B38: 雑シーリング | C38: 開口部等 | D38: 1 | E38: 式 | F38: 30000 | G38: =D38*F38 -> 30000
B39: トップライトガラス廻り シーリング | C39: シリコン | D39: 2 | E39: 箇所 | F39: 5000 | G39: =D39*F39 -> 10000
B40: 小計 | G40: =SUM(G37:G39) -> 482750
...

Sheet 請求書
H1: 45200
A2: 請 求 書
A4: =工事概要!B8 -> 住林林業ホームテック㈱ | C4: 御中 | G4: 住 所 | H4: =工事概要!F3 -> 神奈川県横浜市旭区希望ヶ丘230-9
G5: 工 事 件 名 | H5: =工事概要!B3 -> 住吉屋様邸 改修工事
B6: 請求金額
B7: =G21 -> 0 | G7: 施 工 日 | H7: =工事概要!E10
G8: 担 当 者 | H8: =工事概要!H1 -> 伊藤 隆一
A9: 建設業許可 東京都知事（特-7）第20865号
A10: 名 称 | C10: 仕 様 | D10: 数 量 | E10: 単位 | F10: 単 価 | G10: 金 額 | H10: 摘 要
A11: 1 | B11: 壁 PB面 | E11: ㎡ | G11: =D11*F11 -> 0
A12: 2 | B12: 壁 PB面 | E12: ㎡ | G12: =D12*F12 -> 0
A13: 3 | B13: 諸経費 | D13: 1 | E13: 式 | G13: =SUM(G$11:G12)*0.1 -> 0
A14: 4 | B14: (小 計） | G14: =SUBTOTAL(9,G$11:G13) -> 0
A15: 5 | B15: 値引き | G15: =ROUNDDOWN(G14*1,-4)-G14 -> 0
A16: 6
A17: 7
A18: 8
A19: 9 | B19: 工 事 計 | G19: =SUBTOTAL(9,G$11:G18) -> 0
A20: 10 | B20: 消費税 | D20: 10 | E20: ％ | G20: =G19*D20/100 -> 0
B21: 合 計 | G21: =SUBTOTAL(9,G$11:G20) -> 0
B22: 振込先銀行
B23: 三井住友銀行 | C23: 経堂支店 | D23: 当座預金 | E23: № | F23: ５０３７９７３
B24: みずほ銀行 | C24: 玉川支店 | D24: 当座預金 | E24: № | F24: ４４７７
B25: 横浜銀行 | C25: 玉川支店 | D25: 当座預金 | E25: № | F25: ２４９５

Sheet 指示書
A1: 施 工 指 示 書
F2: 平成 年 月 日
C3: 様 | D3: ご記入の上、ご返信ください。
B4: 現 場 名 | C4: =工事概要!B3 -> 住吉屋様邸 改修工事
B5: 現場住所 | C5: =工事概要!F3 -> 神奈川県横浜市旭区希望ヶ丘230-9
B6: 現 場 ℡ | C6: =工事概要!H4 -> 0 | F6: 現場案内図の添付をお願い致します。
B7: 設計社名 | C7: =工事概要!H6 -> 0
B8: 現場見本 | C8: (有・無) | D8: ○を付けて下さい | F8: サンプル№
F9: 設計社に見本が提出されていますので、必ず現場にご持参ください。
B10: 数量内訳
B11: 施工場所 | C11: 下地材 | D11: 数量 | E11: 単位 | F11: 商品名・仕上げ・色番号
B12: =見積書!B11 -> 外壁塗装工事 | D12: =見積書!D11 -> 1 | E12: =見積書!E11 -> 式 | F12: =見積書!C11&" "&見積書!H11
B13: =見積書!B12 -> 0 | D13: =見積書!D12 -> 0 | E13: =見積書!E12 -> 0 | F13: =見積書!C12&" "&見積書!H12
B14: =見積書!B13 -> 0 | D14: =見積書!D13 -> 0 | E14: =見積書!E13 -> 0 | F14: =見積書!C13&" "&見積書!H13
B15: =見積書!B14 -> 0 | D15: =見積書!D14 -> 0 | E15: =見積書!E14 -> 0 | F15: =見積書!C14&" "&見積書!H14
B16: =見積書!B15 -> 0 | D16: =見積書!D15 -> 0 | E16: =見積書!E15 -> 0 | F16: =見積書!C15&" "&見積書!H15
B17: =見積書!B16 -> 0 | D17: =見積書!D16 -> 0 | E17: =見積書!E16 -> 0 | F17: =見積書!C16&" "&見積書!H16
B18: =見積書!B17 -> 0 | D18: =見積書!D17 -> 0 | E18: =見積書!E17 -> 0 | F18: =見積書!C17&" "&見積書!H17
B19: =見積書!B18 -> 値引き | D19: =見積書!D18 -> 0 | E19: =見積書!E18 -> 0 | F19: =見積書!C18&" "&見積書!H18
B20: 天井高 ｍ | C20: 合 計 | D20: =SUM(D12:D19) -> 1 | E20: ㎡
B22: 施工予定日 | C22: =工事概要!B5 | F22: 年 月 日（ 日間）
B23: 御社支払条件 | C23: 請求 日締 日払（内訳 ）
B24: 御 社 名 | C24: =工事概要!B8 -> 住林林業ホームテック㈱ | F24: （元請 ）
B25: ご 住 所 | C25: （〒 - ）
B27: ＴＥＬ | E27: ＦＡＸ
B28: ご担当者名(携帯番号) | E28: 現場ご担当者名(携帯番号)
B29: =工事概要!E8 -> 吉田
B30: 安全用具 1.必要なものに○を付けて下さい ヘルメット・安全帯・安全靴・長袖・上履き 2. 不要
D31: 新規入場 朝礼・待合せ 時 分 場所
B33: 〒157-0074 | D33: 【備考】
B34: 東京都世田谷区大蔵６－１－３
B35: TEL ０３（３４１７）１３４１
B36: FAX ０３（３４１６）１０６５
B37: 【当社担当者】
B38: =工事概要!H1 -> 伊藤 隆一

Sheet 予算管理
A1: 現場名 | B1: =工事概要!B3 -> 住吉屋様邸 改修工事 | G1: 得意先 | H1: =工事概要!B4 -> 住林林業ホームテック㈱
A3: 工事種目 | B3: 施工班 | C3: 実行予算 | D3: 支払合計 | E3: 実行予算残額 | F3: 月別支払額
F4: =工事概要!B5 | G4: =IF(F4="","",DATE(YEAR(F4),MONTH(F4)+1,1)) -> #VALUE! | H4: =IF(G4="","",DATE(YEAR(G4),MONTH(G4)+1,1)) -> #VALUE! | I4: =IF(H4="","",DATE(YEAR(H4),MONTH(H4)+1,1)) -> #VALUE! | J4: =IF(I4="","",DATE(YEAR(I4),MONTH(I4)+1,1)) -> #VALUE! | K4: =IF(J4="","",DATE(YEAR(J4),MONTH(J4)+1,1)) -> #VALUE!
A5: 塗装工事 | D5: =SUM(F5:K5) -> 0 | E5: =C5-D5 -> 0
D6: =SUM(F6:K6) -> 0 | E6: =C6-D6 -> 0
D7: =SUM(F7:K7) -> 0 | E7: =C7-D7 -> 0
D8: =SUM(F8:K8) -> 0 | E8: =C8-D8 -> 0
D9: =SUM(F9:K9) -> 0 | E9: =C9-D9 -> 0
D10: =SUM(F10:K10) -> 0 | E10: =C10-D10 -> 0
A11: 労務費 計 | C11: =SUBTOTAL(9,C5:C10) -> 0 | D11: =SUBTOTAL(9,D5:D10) -> 0 | E11: =C11-D11 -> 0 | F11: =SUBTOTAL(9,F5:F10) -> 0 | G11: =SUBTOTAL(9,G5:G10) -> 0 | H11: =SUBTOTAL(9,H5:H10) -> 0 | I11: =SUBTOTAL(9,I5:I10) -> 0 | J11: =SUBTOTAL(9,J5:J10) -> 0 | K11: =SUBTOTAL(9,K5:K10) -> 0
D12: =SUM(F12:K12) -> 0 | E12: =C12-D12 -> 0
D13: =SUM(F13:K13) -> 0 | E13: =C13-D13 -> 0
D14: =SUM(F14:K14) -> 0 | E14: =C14-D14 -> 0
D15: =SUM(F15:K15) -> 0 | E15: =C15-D15 -> 0
D16: =SUM(F16:K16) -> 0 | E16: =C16-D16 -> 0
A17: 外注費 計 | C17: =SUBTOTAL(9,C12:C16) -> 0 | D17: =SUBTOTAL(9,D12:D16) -> 0 | E17: =C17-D17 -> 0 | F17: =SUBTOTAL(9,F12:F16) -> 0 | G17: =SUBTOTAL(9,G12:G16) -> 0 | H17: =SUBTOTAL(9,H12:H16) -> 0 | I17: =SUBTOTAL(9,I12:I16) -> 0 | J17: =SUBTOTAL(9,J12:J16) -> 0 | K17: =SUBTOTAL(9,K12:K16) -> 0
A18: 材料 | B18: 三和塗料 | D18: =SUM(F18:K18) -> 0 | E18: =C18-D18 -> 0
B19: 三興塗料 | D19: =SUM(F19:K19) -> 0 | E19: =C19-D19 -> 0
B20: 東海塗料興業 | D20: =SUM(F20:K20) -> 0 | E20: =C20-D20 -> 0
D21: =SUM(F21:K21) -> 0 | E21: =C21-D21 -> 0
D22: =SUM(F22:K22) -> 0 | E22: =C22-D22 -> 0
D23: =SUM(F23:K23) -> 0 | E23: =C23-D23 -> 0
D24: =SUM(F24:K24) -> 0 | E24: =C24-D24 -> 0
A25: 材料費 計 | C25: =SUBTOTAL(9,C18:C24) -> 0 | D25: =SUBTOTAL(9,D18:D24) -> 0 | E25: =SUBTOTAL(9,E18:E24) -> 0 | F25: =SUBTOTAL(9,F18:F24) -> 0 | G25: =SUBTOTAL(9,G18:G24) -> 0 | H25: =SUBTOTAL(9,H18:H24) -> 0 | I25: =SUBTOTAL(9,I18:I24) -> 0 | J25: =SUBTOTAL(9,J18:J24) -> 0 | K25: =SUBTOTAL(9,K18:K24) -> 0
A26: その他 | D26: =SUM(F26:K26) -> 0 | E26: =C26-D26 -> 0
D27: =SUM(F27:K27) -> 0 | E27: =C27-D27 -> 0
D28: =SUM(F28:K28) -> 0 | E28: =C28-D28 -> 0
A29: その他 計 | C29: =SUBTOTAL(9,C26:C28) -> 0 | D29: =SUBTOTAL(9,D26:D28) -> 0 | E29: =SUBTOTAL(9,E26:E28) -> 0 | F29: =SUBTOTAL(9,F26:F28) -> 0 | G29: =SUBTOTAL(9,G26:G28) -> 0 | H29: =SUBTOTAL(9,H26:H28) -> 0 | I29: =SUBTOTAL(9,I26:I28) -> 0 | J29: =SUBTOTAL(9,J26:J28) -> 0 | K29: =SUBTOTAL(9,K26:K28) -> 0
A30: 支払合計 | C30: =SUBTOTAL(9,C5:C29) -> 0 | D30: =SUBTOTAL(9,D5:D29) -> 0 | E30: =SUBTOTAL(9,E5:E29) -> 0 | F30: =SUBTOTAL(9,F5:F29) -> 0 | G30: =SUBTOTAL(9,G5:G29) -> 0 | H30: =SUBTOTAL(9,H5:H29) -> 0 | I30: =SUBTOTAL(9,I5:I29) -> 0 | J30: =SUBTOTAL(9,J5:J29) -> 0 | K30: =SUBTOTAL(9,K5:K29) -> 0
A31: 請求内訳 | C31: 取極額/予算 | D31: 出来高請求額 | E31: 繰越請求額 | F31: 月別売上額
F32: =F4 | G32: =G4 -> #VALUE! | H32: =H4 -> #VALUE! | I32: =I4 -> #VALUE! | J32: =J4 -> #VALUE! | K32: =K4 -> #VALUE!
A33: 請求額 | D33: =SUM(F33:K33) -> 0 | E33: =C33-D33 -> 0
A34: 支払額 | C34: =C30 -> 0 | D34: =D30 -> 0 | E34: =E30 -> 0 | F34: =F30 -> 0 | G34: =G30 -> 0 | H34: =H30 -> 0 | I34: =I30 -> 0 | J34: =J30 -> 0 | K34: =K30 -> 0
A35: 粗利益 | C35: =C33-C34 -> 0 | D35: =D33-D34 -> 0 | E35: =E33-E34 -> 0 | F35: =F33-F34 -> 0 | G35: =G33-G34 -> 0 | H35: =H33-H34 -> 0 | I35: =I33-I34 -> 0 | J35: =J33-J34 -> 0 | K35: =K33-K34 -> 0
A36: 利益比率 | C36: =C35/C33 -> #DIV/0! | D36: =D35/D33 -> #DIV/0!
